<sdf version="1.4">

    <world name="fin_world">
        <physics name="1ms" type="ignored">
            <max_step_size>0.001</max_step_size>
            <real_time_factor>1.0</real_time_factor>
        </physics>
        <plugin
            filename="libignition-gazebo-physics-system.so"
            name="ignition::gazebo::systems::Physics">
        </plugin>
        <plugin
            filename="libignition-gazebo-user-commands-system.so"
            name="ignition::gazebo::systems::UserCommands">
        </plugin>
        <plugin
            filename="libignition-gazebo-scene-broadcaster-system.so"
            name="ignition::gazebo::systems::SceneBroadcaster">
        </plugin>

        <light type="directional" name="sun">
            <cast_shadows>true</cast_shadows>
            <pose>0 0 10 0 0 0</pose>
            <diffuse>0.8 0.8 0.8 1</diffuse>
            <specular>0.2 0.2 0.2 1</specular>
            <attenuation>
                <range>1000</range>
                <constant>0.9</constant>
                <linear>0.01</linear>
                <quadratic>0.001</quadratic>
            </attenuation>
            <direction>-0.5 0.1 -0.9</direction>
        </light>

        <model name="ground_plane">
            <static>true</static>
            <link name="link">
                <collision name="collision">
                    <geometry>
                        <plane>
                            <normal>0 0 1</normal>
                        </plane>
                    </geometry>
                </collision>
                <visual name="visual">
                    <geometry>
                        <plane>
                            <normal>0 0 1</normal>
                            <size>100 100</size>
                        </plane>
                    </geometry>
                    <material>
                        <ambient>0.8 0.8 0.8 1</ambient>
                        <diffuse>0.8 0.8 0.8 1</diffuse>
                        <specular>0.8 0.8 0.8 1</specular>
                    </material>
                </visual>
            </link>
        </model>

        <model name="closed_chain">
            <link name="right_pad1">
                <self_collide>0</self_collide>
                <pose>0.5 0 0 0 0 0</pose>
                <collision name="right_pad1_collision">
                    <geometry>
                        <box>
                            <size>1.0 1.0 0.1</size>
                        </box>
                    </geometry>
                </collision>

                <visual name="right_pad1_visual">
                    <geometry>
                        <box>
                            <size>1.0 1.0 0.1</size>
                        </box>
                    </geometry>

                    <material>
                        <ambient>0.0 0.0 1.0 1</ambient>
                        <diffuse>0.0 0.0 1.0 1</diffuse>
                        <specular>0.0 0.0 1.0 1</specular>
                    </material>
                </visual>

            </link>

            <joint type="revolute" name="right_pad_joint1">
                <pose>-0.5 0 0 0 0 0</pose>
                <parent>right_pad1</parent>
                <child>right_pad2</child>
                <axis>
                    <xyz>0 1 0</xyz>
                </axis>
            </joint>

            <link name="right_pad2">
                <self_collide>0</self_collide>
                <pose>1.0 0 0.5 0 -1.57079632679 0</pose>
                <collision name="right_pad2_collision">
                    <geometry>
                        <box>
                            <size>1.0 1.0 0.1</size>
                        </box>
                    </geometry>
                </collision>

                <visual name="right_pad2_visual">
                    <geometry>
                        <box>
                            <size>1.0 1.0 0.1</size>
                        </box>
                    </geometry>

                    <material>
                        <ambient>0.0 1.0 0.0 1</ambient>
                        <diffuse>0.0 1.0 0.0 1</diffuse>
                        <specular>0.0 1.0 0.0 1</specular>
                    </material>
                </visual>

            </link>

            <joint type="revolute" name="right_pad_joint2">
                <pose>-0.5 0 0 0 0 0</pose>
                <parent>right_pad2</parent>
                <child>right_pad3</child>
                <axis>
                    <xyz>0 1 0</xyz>
                </axis>
            </joint>

            <link name="right_pad3">
                <self_collide>0</self_collide>
                <pose>0.5 0 1 0 -3.1415926536 0</pose>
                <collision name="right_pad3_collision">
                    <geometry>
                        <box>
                            <size>1.0 1.0 0.1</size>
                        </box>
                    </geometry>
                </collision>

                <visual name="right_pad3_visual">
                    <geometry>
                        <box>
                            <size>1.0 1.0 0.1</size>
                        </box>
                    </geometry>

                    <material>
                        <ambient>1.0 0.0 0.0 1</ambient>
                        <diffuse>1.0 0.0 0.0 1</diffuse>
                        <specular>1.0 0.0 0.0 1</specular>
                    </material>
                </visual>

            </link>

            <joint type="revolute" name="right_pad_joint3">
                <pose>-0.5 0 0 0 0 0</pose>
                <parent>right_pad3</parent>
                <child>right_pad4</child>
                <axis>
                    <xyz>0 1 0</xyz>
                </axis>
            </joint>

            <link name="right_pad4">
                <self_collide>0</self_collide>
                <pose>0 0 0.5 0 -4.7123889804 0</pose>
                <collision name="right_pad4_collision">
                    <geometry>
                        <box>
                            <size>1.0 1.0 0.1</size>
                        </box>
                    </geometry>
                </collision>

                <visual name="right_pad4_visual">
                    <geometry>
                        <box>
                            <size>1.0 1.0 0.1</size>
                        </box>
                    </geometry>

                    <material>
                        <ambient>0.5 0.0 0.5 1</ambient>
                        <diffuse>0.5 0.0 0.5 1</diffuse>
                        <specular>0.5 0.0 0.5 1</specular>
                    </material>
                </visual>

            </link>

            <joint type="revolute" name="right_pad_joint4">
                <pose>-0.5 0 0 0 0 0</pose>
                <parent>right_pad4</parent>
                <child>right_pad1</child>
                <axis>
                    <xyz>0 1 0</xyz>
                </axis>
            </joint>

        </model>
    </world>
</sdf>