<?xml version="1.0"?>
<sdf version="1.4">
  <world name="fin_world">
    <include>
      <uri>model://ground_plane</uri>
    </include>
    <include>
      <uri>model://sun</uri>
    </include>

    <model name="fin_mechanism">

      <pose relative_to='world'>0 0 0 0 0 0</pose>

      <link name='base_link'>
        <inertial>
          <pose>-0.036030663321934601 0.59638474826819721 0.04700297266298855 0 0 0</pose>
          <mass>0.0080817471013597455</mass>
          <inertia>
            <ixx>3.0000000000000001e-05</ixx>
            <ixy>0</ixy>
            <ixz>0</ixz>
            <iyy>0</iyy>
            <iyz>0</iyz>
            <izz>3.0000000000000001e-05</izz>
          </inertia>
        </inertial>
        <collision name='base_link_collision'>
          <pose>0 0 0 0 0 0</pose>
          <geometry>
            <mesh>
              <scale>0.001 0.001 0.001</scale>
              <uri>file://meshes/base_link.stl</uri>
            </mesh>
          </geometry>
        </collision>
        <visual name='base_link_visual'>
          <pose>0 0 0 0 0 0</pose>
          <geometry>
            <mesh>
              <scale>0.001 0.001 0.001</scale>
              <uri>file://meshes/base_link.stl</uri>
            </mesh>
          </geometry>
          <material>
            <diffuse>0 0 0 1</diffuse>
            <ambient>0 0 0 1</ambient>
          </material>
        </visual>
      </link>
      <joint name='revolucion1' type='revolute'>
        <pose relative_to='base_link'>-0.036031000000000001 0.70138500000000004 0.047095999999999999 0 0 0</pose>
        <parent>base_link</parent>
        <child>input_bar_1_1</child>
        <axis>
          <xyz>-5.0000000000000004e-06 1 0.00088400000000000002</xyz>
          <limit>
            <lower>-inf</lower>
            <upper>inf</upper>
          </limit>
          <dynamics>
            <spring_reference>0</spring_reference>
            <spring_stiffness>0</spring_stiffness>
          </dynamics>
        </axis>
      </joint>
      <link name='input_bar_1_1'>
        <pose relative_to='revolucion1'>0 0 0 0 0 0</pose>
        <inertial>
          <pose>-0.027484096297025949 -0.01101397279025618 0.015329729548726819 0 0 0</pose>
          <mass>0.040656388446325881</mass>
          <inertia>
            <ixx>1.2e-05</ixx>
            <ixy>0</ixy>
            <ixz>1.5999999999999999e-05</ixz>
            <iyy>4.1e-05</iyy>
            <iyz>0</iyz>
            <izz>3.1000000000000001e-05</izz>
          </inertia>
        </inertial>
        <collision name='input_bar_1_1_collision'>
          <pose>0.036031000000000001 -0.70138500000000004 -0.047095999999999999 0 0 0</pose>
          <geometry>
            <mesh>
              <scale>0.001 0.001 0.001</scale>
              <uri>file://meshes/input_bar_1_1.stl</uri>
            </mesh>
          </geometry>
        </collision>
        <visual name='input_bar_1_1_visual'>
          <pose>0.036031000000000001 -0.70138500000000004 -0.047095999999999999 0 0 0</pose>
          <geometry>
            <mesh>
              <scale>0.001 0.001 0.001</scale>
              <uri>file://meshes/input_bar_1_1.stl</uri>
            </mesh>
          </geometry>
          <material>
            <diffuse>0 0 0 1</diffuse>
            <ambient>0 0 0 1</ambient>
          </material>
        </visual>
      </link>
      <joint name='input1_to_hook' type='prismatic'>
        <pose relative_to='input_bar_1_1'>-0.078782000000000005 -0.011039 0.043506999999999997 0 0 0</pose>
        <parent>input_bar_1_1</parent>
        <child>hook_to_slider_1</child>
        <axis>
          <xyz>0.872637 0.00043600000000000003 -0.488369</xyz>
          <limit>
            <lower>-0.017999999999999999</lower>
            <upper>0.018499999999999999</upper>
            <effort>100</effort>
            <velocity>100</velocity>
          </limit>
          <dynamics>
            <spring_reference>0</spring_reference>
            <spring_stiffness>0</spring_stiffness>
          </dynamics>
        </axis>
      </joint>
      <link name='hook_to_slider_1'>
        <pose relative_to='input1_to_hook'>0 0 0 0 0 0</pose>
        <inertial>
          <pose>-0.0056460439507312471 -2.9323806829406611e-06 0.0031599708182316472 0 0 0</pose>
          <mass>0.030364421078294609</mass>
          <inertia>
            <ixx>3.0000000000000001e-06</ixx>
            <ixy>0</ixy>
            <ixz>3.0000000000000001e-06</ixz>
            <iyy>1.0000000000000001e-05</iyy>
            <iyz>0</iyz>
            <izz>6.9999999999999999e-06</izz>
          </inertia>
        </inertial>
        <collision name='hook_to_slider_1_collision'>
          <pose>0.114813 -0.69034600000000002 -0.090603000000000003 0 0 0</pose>
          <geometry>
            <mesh>
              <scale>0.001 0.001 0.001</scale>
              <uri>file://meshes/hook_to_slider_1.stl</uri>
            </mesh>
          </geometry>
        </collision>
        <visual name='hook_to_slider_1_visual'>
          <pose>0.114813 -0.69034600000000002 -0.090603000000000003 0 0 0</pose>
          <geometry>
            <mesh>
              <scale>0.001 0.001 0.001</scale>
              <uri>file://meshes/hook_to_slider_1.stl</uri>
            </mesh>
          </geometry>
          <material>
            <diffuse>0 0 0 1</diffuse>
            <ambient>0 0 0 1</ambient>
          </material>
        </visual>
      </link>

      <!-- Duplicated -->


      <!-- <joint name='spherical_joint_1' type='revolute'>
        <pose relative_to='hook_to_slider_1'>-0.014061000000000001 -6.9999999999999999e-06 0.0078689999999999993 0 0 0</pose>
        <parent>hook_to_slider_1</parent>
        <child>ball_slider_1</child>
        <axis>
          <xyz>-0.0058199999999999997 -0.96717900000000001 -0.254029</xyz>
          <limit>
            <lower>-inf</lower>
            <upper>inf</upper>
          </limit>
          <dynamics>
            <spring_reference>0</spring_reference>
            <spring_stiffness>0</spring_stiffness>
          </dynamics>
        </axis>
      </joint> -->


      <!-- <link name='ball_slider_1'>
        <pose relative_to='spherical_joint_1'>0 0 0 0 0 0</pose>
        <inertial>
          <pose>2.9965942252574429e-07 -1.3310900448537671e-07 2.1484172495200851e-07 0 0 0</pose>
          <mass>0.00055475290274639732</mass>
          <inertia>
            <ixx>0</ixx>
            <ixy>0</ixy>
            <ixz>0</ixz>
            <iyy>0</iyy>
            <iyz>0</iyz>
            <izz>0</izz>
          </inertia>
        </inertial>
        <collision name='ball_slider_1_collision'>
          <pose>0.12887399999999999 -0.69033900000000004 -0.098472000000000004 0 0 0</pose>
          <geometry>
            <mesh>
              <scale>0.001 0.001 0.001</scale>
              <uri>file://meshes/ball_slider_1.stl</uri>
            </mesh>
          </geometry>
        </collision>
        <visual name='ball_slider_1_visual'>
          <pose>0.12887399999999999 -0.69033900000000004 -0.098472000000000004 0 0 0</pose>
          <geometry>
            <mesh>
              <scale>0.001 0.001 0.001</scale>
              <uri>file://meshes/ball_slider_1.stl</uri>
            </mesh>
          </geometry>
          <material>
            <diffuse>0 0 0 1</diffuse>
            <ambient>0 0 0 1</ambient>
          </material>
        </visual>
      </link> -->


      <joint name='revolucion2' type='revolute'>
        <pose relative_to='base_link'>-0.03603 0.49138500000000002 0.04691 0 0 0</pose>
        <parent>base_link</parent>
        <child>input_bar_2_1</child>
        <axis>
          <xyz>5.0000000000000004e-06 -1 -0.00088400000000000002</xyz>
          <limit>
            <lower>-inf</lower>
            <upper>inf</upper>
          </limit>
          <dynamics>
            <spring_reference>0</spring_reference>
            <spring_stiffness>0</spring_stiffness>
          </dynamics>
        </axis>
      </joint>
      <link name='input_bar_2_1'>
        <pose relative_to='revolucion2'>0 0 0 0 0 0</pose>
        <inertial>
          <pose>-0.037788274331815953 0.0089988888589823124 0.00082006022399550016 0 0 0</pose>
          <mass>0.045897665945782408</mass>
          <inertia>
            <ixx>3.0000000000000001e-06</ixx>
            <ixy>0</ixy>
            <ixz>9.9999999999999995e-07</ixz>
            <iyy>5.5999999999999999e-05</iyy>
            <iyz>0</iyz>
            <izz>5.5999999999999999e-05</izz>
          </inertia>
        </inertial>
        <collision name='input_bar_2_1_collision'>
          <pose>0.03603 -0.49138500000000002 -0.04691 0 0 0</pose>
          <geometry>
            <mesh>
              <scale>0.001 0.001 0.001</scale>
              <uri>file://meshes/input_bar_2_1.stl</uri>
            </mesh>
          </geometry>
        </collision>
        <visual name='input_bar_2_1_visual'>
          <pose>0.03603 -0.49138500000000002 -0.04691 0 0 0</pose>
          <geometry>
            <mesh>
              <scale>0.001 0.001 0.001</scale>
              <uri>file://meshes/input_bar_2_1.stl</uri>
            </mesh>
          </geometry>
          <material>
            <diffuse>0 0 0 1</diffuse>
            <ambient>0 0 0 1</ambient>
          </material>
        </visual>
      </link>
      <joint name='input2_to_attatchment' type='prismatic'>
        <pose relative_to='input_bar_2_1'>0.59937600000000002 0.32805699999999999 -0.063697000000000004 0 0 0</pose>
        <parent>input_bar_2_1</parent>
        <child>attatchment_1</child>
        <axis>
          <xyz>-0.99973500000000004 -2.5000000000000001e-05 0.023002000000000002</xyz>
          <limit>
            <lower>-0.017999999999999999</lower>
            <upper>0.018499999999999999</upper>
            <effort>100</effort>
            <velocity>100</velocity>
          </limit>
          <dynamics>
            <spring_reference>0</spring_reference>
            <spring_stiffness>0</spring_stiffness>
          </dynamics>
        </axis>
      </joint>
      <link name='attatchment_1'>
        <pose relative_to='input2_to_attatchment'>0 0 0 0 0 0</pose>
        <inertial>
          <pose>-0.82370137434792867 -0.21731084830848821 0.089360652771222043 0 0 0</pose>
          <mass>6.462426001735782</mass>
          <inertia>
            <ixx>0.047037545185524443</ixx>
            <ixy>-0.001913982569610839</ixy>
            <ixz>0.0012135764642877691</ixz>
            <iyy>0.07160941131564158</iyy>
            <iyz>-0.01062818348767175</iyz>
            <izz>0.1103913635450926</izz>
          </inertia>
        </inertial>
        <collision name='attatchment_1_collision'>
          <pose>-0.56334600000000001 -0.819442 0.016787 0 0 0</pose>
          <geometry>
            <mesh>
              <scale>0.001 0.001 0.001</scale>
              <uri>file://meshes/attatchment_1.stl</uri>
            </mesh>
          </geometry>
        </collision>
        <collision name='attatchment_1_fixed_joint_lump__fin_1_collision_1'>
          <pose>-0.5633459999999999 -0.819442 0.016787 0 0 0</pose>
          <geometry>
            <mesh>
              <scale>0.001 0.001 0.001</scale>
              <uri>file://meshes/fin_1.stl</uri>
            </mesh>
          </geometry>
        </collision>
        <visual name='attatchment_1_visual'>
          <pose>-0.56334600000000001 -0.819442 0.016787 0 0 0</pose>
          <geometry>
            <mesh>
              <scale>0.001 0.001 0.001</scale>
              <uri>file://meshes/attatchment_1.stl</uri>
            </mesh>
          </geometry>
          <material>
            <diffuse>0 0 0 1</diffuse>
            <ambient>0 0 0 1</ambient>
          </material>
        </visual>
        <visual name='attatchment_1_fixed_joint_lump__fin_1_visual_1'>
          <pose>-0.5633459999999999 -0.819442 0.016787 0 0 0</pose>
          <geometry>
            <mesh>
              <scale>0.001 0.001 0.001</scale>
              <uri>file://meshes/fin_1.stl</uri>
            </mesh>
          </geometry>
          <material>
            <diffuse>0 0 0 1</diffuse>
            <ambient>0 0 0 1</ambient>
          </material>
        </visual>
      </link>
      <joint name='spherical_joint_1' type='revolute'>
        <pose relative_to='hook_to_slider_1'>-0.014061000000000001 -6.9999999999999999e-06 0.0078689999999999993 0 0 0</pose>
        <parent>hook_to_slider_1</parent>
        <child>ball_slider_1</child>
        <axis>
          <xyz>-0.0058199999999999997 -0.96717900000000001 -0.254029</xyz>
          <limit>
            <lower>-inf</lower>
            <upper>inf</upper>
          </limit>
          <dynamics>
            <spring_reference>0</spring_reference>
            <spring_stiffness>0</spring_stiffness>
          </dynamics>
        </axis>
      </joint>
      <link name='ball_slider_1'>
        <pose relative_to='spherical_joint_1'>0 0 0 0 0 0</pose>
        <inertial>
          <pose>2.9965942252574429e-07 -1.3310900448537671e-07 2.1484172495200851e-07 0 0 0</pose>
          <mass>0.00055475290274639732</mass>
          <inertia>
            <ixx>0</ixx>
            <ixy>0</ixy>
            <ixz>0</ixz>
            <iyy>0</iyy>
            <iyz>0</iyz>
            <izz>0</izz>
          </inertia>
        </inertial>
        <collision name='ball_slider_1_collision'>
          <pose>0.12887399999999999 -0.69033900000000004 -0.098472000000000004 0 0 0</pose>
          <geometry>
            <mesh>
              <scale>0.001 0.001 0.001</scale>
              <uri>file://meshes/ball_slider_1.stl</uri>
            </mesh>
          </geometry>
        </collision>
        <visual name='ball_slider_1_visual'>
          <pose>0.12887399999999999 -0.69033900000000004 -0.098472000000000004 0 0 0</pose>
          <geometry>
            <mesh>
              <scale>0.001 0.001 0.001</scale>
              <uri>file://meshes/ball_slider_1.stl</uri>
            </mesh>
          </geometry>
          <material>
            <diffuse>0 0 0 1</diffuse>
            <ambient>0 0 0 1</ambient>
          </material>
        </visual>
      </link>
      <frame name='fin_attatchment' attached_to='attatchment_1'>
        <pose>-0.82118899999999995 -0.46016299999999999 0.62803900000000001 0 0 0</pose>
      </frame>
      <frame name='fin_1' attached_to='fin_attatchment'>
        <pose>0 0 0 0 0 0</pose>
      </frame>
    </model>
  </world>
  </sdf>

  